Workbook

Sheet PORTADA
B2: REPORTE DE ACTIVIDADES ASISTENCIA Y PROFESORES
B4: HOJAS | C4: DESCRIPCION
B5: 1 – ACTIVIDADES | C5: Listado de actividades unicas
B6: 2 – PROFESORES | C6: Listado de profesores dictando actividades
B7: 3 – ASISTENCIA | C7: Listado de concurrencia a las actividades
B8: 4 – TABLAS | C8: Tablas informativas con datos maximos y minimos
B9: 5 – GRAFICOS | C9: Graficos ilistrativos de las tablas
B12: Profesional: Gonzalo Aguirre –– ▶Tel: 3513271784 ▶ V1

Sheet 1 – ACTIVIDADES
B2: N° | C2: ACTIVIDAD | D2: DESDE | E2: HASTA | F2: ACTIVA/ INACTIVA | G2: DIAS | H2: HORARIOS | I2: CUPOS
B3: 1 | C3: =UPPER(actividad[[#This Row],[ACTIVIDAD]]) -> CALISTENIA
B4: 2 | C4: =UPPER(actividad[[#This Row],[ACTIVIDAD]]) -> BOXEO
B5: 3 | C5: =UPPER(actividad[[#This Row],[ACTIVIDAD]]) -> MMA+BOXEO
B6: 4 | C6: =UPPER(actividad[[#This Row],[ACTIVIDAD]]) -> KARATE
B7: 5 | C7: =UPPER(actividad[[#This Row],[ACTIVIDAD]]) -> TAEKWONDO
B8: 6 | C8: =UPPER(actividad[[#This Row],[ACTIVIDAD]]) -> TELA
B9: 7 | C9: =UPPER(actividad[[#This Row],[ACTIVIDAD]]) -> LYRA
B10: 8 | C10: =UPPER(actividad[[#This Row],[ACTIVIDAD]]) -> YOGA Y YOGA COLUMPIO
B11: 9 | C11: =UPPER(actividad[[#This Row],[ACTIVIDAD]]) -> POLE SPORT
B12: 10 | C12: =UPPER(actividad[[#This Row],[ACTIVIDAD]]) -> ACRO KIDS
B13: 11 | C13: =UPPER(actividad[[#This Row],[ACTIVIDAD]]) -> MOVIMIENTO CONSCIENTE
B14: 12 | C14: =UPPER(actividad[[#This Row],[ACTIVIDAD]]) -> CROSS TRANING
... B20: 18 | C20: =UPPER(actividad[[#This Row],[ACTIVIDAD]]) -> NUTRICION

Sheet 2 – PROFESORES
B2: N° | C2: PROFESOR | D2: ACTIVIDAD | E2: HORARIO | F2: CONTACTO
B3: 1 | C3: Agus
B4: 2 | C4: Edd
B5: 3 | C5: Lazaro
B6: 4 | C6: Lean
B7: 5 | C7: Marco
B8: 6 | C8: Mariano
B9: 7 | C9: Martin
B10: 8 | C10: Paula
B11: 9 | C11: Tito

Sheet 3 – ASISTENCIA
A1: SEMANA | B1: FECHA | C1: MES NUMERO | D1: MES NOMBRE | E1: ACTIVIDAD | F1: ACTIVIDAD GLOBAL | G1: PROFESOR | H1: CANTIDAD DE ALUMNOS | I1: OBSERVACIONES
A2: 1 | B2: 45689 | C2: =TEXT(B2,"mm") -> 02 | D2: =UPPER(TEXT(B2,"mmmm")) -> FEBRERO | E2: Calistenia Edd | F2: =_xlfn.XLOOKUP(E2,MAPEO!$B:$B,MAPEO!$C:$C,"",0) -> Calistenia | G2: =_xlfn.XLOOKUP(E2,MAPEO!$B:$B,MAPEO!$D:$D,"",0) -> Edd
A3: 1 | B3: 45689 | C3: =TEXT(B3,"mm") -> 02 | D3: =UPPER(TEXT(B3,"mmmm")) -> FEBRERO | E3: Calistenia Martin | F3: =_xlfn.XLOOKUP(E3,MAPEO!$B:$B,MAPEO!$C:$C,"",0) -> Calistenia | G3: =_xlfn.XLOOKUP(E3,MAPEO!$B:$B,MAPEO!$D:$D,"",0) -> Martin
A4: 1 | B4: 45689 | C4: =TEXT(B4,"mm") -> 02 | D4: =UPPER(TEXT(B4,"mmmm")) -> FEBRERO | E4: Calistenia Agus | F4: =_xlfn.XLOOKUP(E4,MAPEO!$B:$B,MAPEO!$C:$C,"",0) -> Calistenia | G4: =_xlfn.XLOOKUP(E4,MAPEO!$B:$B,MAPEO!$D:$D,"",0) -> Agus
A5: 1 | B5: 45689 | C5: =TEXT(B5,"mm") -> 02 | D5: =UPPER(TEXT(B5,"mmmm")) -> FEBRERO | E5: Calistenia Lazaro | F5: =_xlfn.XLOOKUP(E5,MAPEO!$B:$B,MAPEO!$C:$C,"",0) -> Calistenia | G5: =_xlfn.XLOOKUP(E5,MAPEO!$B:$B,MAPEO!$D:$D,"",0) -> Lazaro
A6: 1 | B6: 45689 | C6: =TEXT(B6,"mm") -> 02 | D6: =UPPER(TEXT(B6,"mmmm")) -> FEBRERO | E6: Calistenia Paula | F6: =_xlfn.XLOOKUP(E6,MAPEO!$B:$B,MAPEO!$C:$C,"",0) -> Calistenia | G6: =_xlfn.XLOOKUP(E6,MAPEO!$B:$B,MAPEO!$D:$D,"",0) -> Paula
A7: 1 | B7: 45689 | C7: =TEXT(B7,"mm") -> 02 | D7: =UPPER(TEXT(B7,"mmmm")) -> FEBRERO | E7: Boxeo y Kickboxing Mariano | F7: =_xlfn.XLOOKUP(E7,MAPEO!$B:$B,MAPEO!$C:$C,"",0) -> Boxeo | G7: =_xlfn.XLOOKUP(E7,MAPEO!$B:$B,MAPEO!$D:$D,"",0) -> Mariano
A8: 1 | B8: 45689 | C8: =TEXT(B8,"mm") -> 02 | D8: =UPPER(TEXT(B8,"mmmm")) -> FEBRERO | E8: Boxeo tito | F8: =_xlfn.XLOOKUP(E8,MAPEO!$B:$B,MAPEO!$C:$C,"",0) -> Boxeo | G8: =_xlfn.XLOOKUP(E8,MAPEO!$B:$B,MAPEO!$D:$D,"",0) -> tito
A9: 1 | B9: 45689 | C9: =TEXT(B9,"mm") -> 02 | D9: =UPPER(TEXT(B9,"mmmm")) -> FEBRERO | E9: MMA+BOXEO | F9: =_xlfn.XLOOKUP(E9,MAPEO!$B:$B,MAPEO!$C:$C,"",0) -> MMA+BOXEO | G9: –
A10: 1 | B10: 45689 | C10: =TEXT(B10,"mm") -> 02 | D10: =UPPER(TEXT(B10,"mmmm")) -> FEBRERO | E10: Karate | F10: =_xlfn.XLOOKUP(E10,MAPEO!$B:$B,MAPEO!$C:$C,"",0) -> Karate | G10: –
A11: 1 | B11: 45689 | C11: =TEXT(B11,"mm") -> 02 | D11: =UPPER(TEXT(B11,"mmmm")) -> FEBRERO | E11: Taekwondo | F11: =_xlfn.XLOOKUP(E11,MAPEO!$B:$B,MAPEO!$C:$C,"",0) -> Taekwondo | G11: –
A12: 1 | B12: 45689 | C12: =TEXT(B12,"mm") -> 02 | D12: =UPPER(TEXT(B12,"mmmm")) -> FEBRERO | E12: Tela | F12: =_xlfn.XLOOKUP(E12,MAPEO!$B:$B,MAPEO!$C:$C,"",0) -> Tela | G12: –
A13: 1 | B13: 45689 | C13: =TEXT(B13,"mm") -> 02 | D13: =UPPER(TEXT(B13,"mmmm")) -> FEBRERO | E13: Lyra | F13: =_xlfn.XLOOKUP(E13,MAPEO!$B:$B,MAPEO!$C:$C,"",0) -> Lyra | G13: –
A14: 1 | B14: 45689 | C14: =TEXT(B14,"mm") -> 02 | D14: =UPPER(TEXT(B14,"mmmm")) -> FEBRERO | E14: Yoga y Yoga Columpio | F14: =_xlfn.XLOOKUP(E14,MAPEO!$B:$B,MAPEO!$C:$C,"",0) -> Yoga y Yoga Columpio | G14: –
A15: 1 | B15: 45689 | C15: =TEXT(B15,"mm") -> 02 | D15: =UPPER(TEXT(B15,"mmmm")) -> FEBRERO | E15: Pole Sport | F15: =_xlfn.XLOOKUP(E15,MAPEO!$B:$B,MAPEO!$C:$C,"",0) -> Pole Sport | G15: –
A16: 1 | B16: 45689 | C16: =TEXT(B16,"mm") -> 02 | D16: =UPPER(TEXT(B16,"mmmm")) -> FEBRERO | E16: Acro Kids | F16: =_xlfn.XLOOKUP(E16,MAPEO!$B:$B,MAPEO!$C:$C,"",0) -> Acro Kids | G16: –
A17: 1 | B17: 45689 | C17: =TEXT(B17,"mm") -> 02 | D17: =UPPER(TEXT(B17,"mmmm")) -> FEBRERO | E17: Calistenia Kids | F17: =_xlfn.XLOOKUP(E17,MAPEO!$B:$B,MAPEO!$C:$C,"",0) -> Calistenia | G17: –
A18: 1 | B18: 45689 | C18: =TEXT(B18,"mm") -> 02 | D18: =UPPER(TEXT(B18,"mmmm")) -> FEBRERO | E18: Movimiento Consciente | F18: =_xlfn.XLOOKUP(E18,MAPEO!$B:$B,MAPEO!$C:$C,"",0) -> Movimiento Consciente | G18: –
A19: 1 | B19: 45689 | C19: =TEXT(B19,"mm") -> 02 | D19: =UPPER(TEXT(B19,"mmmm")) -> FEBRERO | E19: Cross Traning | F19: =_xlfn.XLOOKUP(E19,MAPEO!$B:$B,MAPEO!$C:$C,"",0) -> Cross Traning | G19: –
A20: 1 | B20: 45689 | C20: =TEXT(B20,"mm") -> 02 | D20: =UPPER(TEXT(B20,"mmmm")) -> FEBRERO | E20: Funcional | F20: =_xlfn.XLOOKUP(E20,MAPEO!$B:$B,MAPEO!$C:$C,"",0) -> Funcional | G20: –
A21: 1 | B21: 45689 | C21: =TEXT(B21,"mm") -> 02 | D21: =UPPER(TEXT(B21,"mmmm")) -> FEBRERO | E21: EFA | F21: =_xlfn.XLOOKUP(E21,MAPEO!$B:$B,MAPEO!$C:$C,"",0) -> EFA | G21: –
A22: 1 | B22: 45689 | C22: =TEXT(B22,"mm") -> 02 | D22: =UPPER(TEXT(B22,"mmmm")) -> FEBRERO | E22: Personalizados Marco | F22: =_xlfn.XLOOKUP(E22,MAPEO!$B:$B,MAPEO!$C:$C,"",0) -> Personalizados | G22: =_xlfn.XLOOKUP(E22,MAPEO!$B:$B,MAPEO!$D:$D,"",0) -> Marco
A23: 1 | B23: 45689 | C23: =TEXT(B23,"mm") -> 02 | D23: =UPPER(TEXT(B23,"mmmm")) -> FEBRERO | E23: Personalizados Lean | F23: =_xlfn.XLOOKUP(E23,MAPEO!$B:$B,MAPEO!$C:$C,"",0) -> Personalizados | G23: =_xlfn.XLOOKUP(E23,MAPEO!$B:$B,MAPEO!$D:$D,"",0) -> Lean
A24: 1 | B24: 45717 | C24: =TEXT(B24,"mm") -> 03 | D24: =UPPER(TEXT(B24,"mmmm")) -> MARZO | E24: Calistenia Edd | F24: =_xlfn.XLOOKUP(E24,MAPEO!$B:$B,MAPEO!$C:$C,"",0) -> Calistenia | G24: =_xlfn.XLOOKUP(E24,MAPEO!$B:$B,MAPEO!$D:$D,"",0) -> Edd | H24: 13
A25: 1 | B25: 45717 | C25: =TEXT(B25,"mm") -> 03 | D25: =UPPER(TEXT(B25,"mmmm")) -> MARZO | E25: Calistenia Martin | F25: =_xlfn.XLOOKUP(E25,MAPEO!$B:$B,MAPEO!$C:$C,"",0) -> Calistenia | G25: =_xlfn.XLOOKUP(E25,MAPEO!$B:$B,MAPEO!$D:$D,"",0) -> Martin | H25: 14
A26: 1 | B26: 45717 | C26: =TEXT(B26,"mm") -> 03 | D26: =UPPER(TEXT(B26,"mmmm")) -> MARZO | E26: Calistenia Agus | F26: =_xlfn.XLOOKUP(E26,MAPEO!$B:$B,MAPEO!$C:$C,"",0) -> Calistenia | G26: =_xlfn.XLOOKUP(E26,MAPEO!$B:$B,MAPEO!$D:$D,"",0) -> Agus | H26: 17
A27: 1 | B27: 45717 | C27: =TEXT(B27,"mm") -> 03 | D27: =UPPER(TEXT(B27,"mmmm")) -> MARZO | E27: Calistenia Lazaro | F27: =_xlfn.XLOOKUP(E27,MAPEO!$B:$B,MAPEO!$C:$C,"",0) -> Calistenia | G27: =_xlfn.XLOOKUP(E27,MAPEO!$B:$B,MAPEO!$D:$D,"",0) -> Lazaro | H27: 6
A28: 1 | B28: 45717 | C28: =TEXT(B28,"mm") -> 03 | D28: =UPPER(TEXT(B28,"mmmm")) -> MARZO | E28: Calistenia Paula | F28: =_xlfn.XLOOKUP(E28,MAPEO!$B:$B,MAPEO!$C:$C,"",0) -> Calistenia | G28: =_xlfn.XLOOKUP(E28,MAPEO!$B:$B,MAPEO!$D:$D,"",0) -> Paula | H28: 3
A29: 1 | B29: 45717 | C29: =TEXT(B29,"mm") -> 03 | D29: =UPPER(TEXT(B29,"mmmm")) -> MARZO | E29: Boxeo y Kickboxing Mariano | F29: =_xlfn.XLOOKUP(E29,MAPEO!$B:$B,MAPEO!$C:$C,"",0) -> Boxeo | G29: =_xlfn.XLOOKUP(E29,MAPEO!$B:$B,MAPEO!$D:$D,"",0) -> Mariano | H29: 11 | I29: pase flex nestor y mariano ESTE ULTIMO(1)
A30: 1 | B30: 45717 | C30: =TEXT(B30,"mm") -> 03 | D30: =UPPER(TEXT(B30,"mmmm")) -> MARZO | E30: Boxeo tito | F30: =_xlfn.XLOOKUP(E30,MAPEO!$B:$B,MAPEO!$C:$C,"",0) -> Boxeo | G30: =_xlfn.XLOOKUP(E30,MAPEO!$B:$B,MAPEO!$D:$D,"",0) -> tito | H30: 8
A31: 1 | B31: 45717 | C31: =TEXT(B31,"mm") -> 03 | D31: =UPPER(TEXT(B31,"mmmm")) -> MARZO | E31: MMA | F31: =_xlfn.XLOOKUP(E31,MAPEO!$B:$B,MAPEO!$C:$C,"",0) -> MMA | G31: – | H31: 2
A32: 1 | B32: 45717 | C32: =TEXT(B32,"mm") -> 03 | D32: =UPPER(TEXT(B32,"mmmm")) -> MARZO | E32: Karate | F32: =_xlfn.XLOOKUP(E32,MAPEO!$B:$B,MAPEO!$C:$C,"",0) -> Karate | G32: – | H32: 0
A33: 1 | B33: 45717 | C33: =TEXT(B33,"mm") -> 03 | D33: =UPPER(TEXT(B33,"mmmm")) -> MARZO | E33: Taekwondo | F33: =_xlfn.XLOOKUP(E33,MAPEO!$B:$B,MAPEO!$C:$C,"",0) -> Taekwondo | G33: – | H33: 2
A34: 1 | B34: 45717 | C34: =TEXT(B34,"mm") -> 03 | D34: =UPPER(TEXT(B34,"mmmm")) -> MARZO | E34: Tela | F34: =_xlfn.XLOOKUP(E34,MAPEO!$B:$B,MAPEO!$C:$C,"",0) -> Tela | G34: – | H34: 3
A35: 1 | B35: 45717 | C35: =TEXT(B35,"mm") -> 03 | D35: =UPPER(TEXT(B35,"mmmm")) -> MARZO | E35: Lyra | F35: =_xlfn.XLOOKUP(E35,MAPEO!$B:$B,MAPEO!$C:$C,"",0) -> Lyra | G35: – | H35: 3
A36: 1 | B36: 45717 | C36: =TEXT(B36,"mm") -> 03 | D36: =UPPER(TEXT(B36,"mmmm")) -> MARZO | E36: Yoga y Yoga Columpio | F36: =_xlfn.XLOOKUP(E36,MAPEO!$B:$B,MAPEO!$C:$C,"",0) -> Yoga y Yoga Columpio | G36: – | H36: 0
A37: 1 | B37: 45717 | C37: =TEXT(B37,"mm") -> 03 | D37: =UPPER(TEXT(B37,"mmmm")) -> MARZO | E37: Pole Sport | F37: =_xlfn.XLOOKUP(E37,MAPEO!$B:$B,MAPEO!$C:$C,"",0) -> Pole Sport | G37: – | H37: 13
A38: 1 | B38: 45717 | C38: =TEXT(B38,"mm") -> 03 | D38: =UPPER(TEXT(B38,"mmmm")) -> MARZO | E38: Acro Kids | F38: =_xlfn.XLOOKUP(E38,MAPEO!$B:$B,MAPEO!$C:$C,"",0) -> Acro Kids | G38: – | H38: 3
A39: 1 | B39: 45717 | C39: =TEXT(B39,"mm") -> 03 | D39: =UPPER(TEXT(B39,"mmmm")) -> MARZO | E39: Calistenia Kids | F39: =_xlfn.XLOOKUP(E39,MAPEO!$B:$B,MAPEO!$C:$C,"",0) -> Calistenia | G39: – | H39: 2
A40: 1 | B40: 45717 | C40: =TEXT(B40,"mm") -> 03 | D40: =UPPER(TEXT(B40,"mmmm")) -> MARZO | E40: Movimiento Consciente | F40: =_xlfn.XLOOKUP(E40,MAPEO!$B:$B,MAPEO!$C:$C,"",0) -> Movimiento Consciente | G40: – | H40: 1
...

Sheet 4 – TABLAS
A1: ALUMNOS POR ACTIVIDAD
A2: ACTIVIDAD GLOBAL | B2: CONTEO DE ALUMNOS
A3: Acro Kids | B3: 72
A4: Boxeo | B4: 520
A5: Calistenia | B5: 1058
A6: Cross Traning | B6: 33
A7: EFA | B7: 101
A8: Funcional | B8: 915
A9: JIU JITSU | B9: 24
A10: Karate | B10: 17
A11: Lyra | B11: 89
A12: MMA | B12: 37
A13: MMA+BOXEO | B13: 25
A14: Movimiento Consciente | B14: 36
A15: Nutricion
A16: Personalizados | B16: 206
A17: Pole Sport | B17: 216
A18: Taekwondo | B18: 7
A19: Tela | B19: 54
A20: Yoga y Yoga Columpio | B20: 32
A21: Total general | B21: 3442
A24: ALUMNOS POR PROFESOR
A25: PROFESOR | B25: CONTEO DE ALUMNOS
A26: Agus | B26: 186
A27: Edd | B27: 295
A28: Lazaro | B28: 150
A29: Lean | B29: 15
A30: Marco | B30: 191
A31: Mariano | B31: 313
A32: Martin | B32: 332
A33: Paula | B33: 64
A34: tito | B34: 207
A35: Total general | B35: 1753
A39: ALUMNOS POR MES
A40: MES NOMBRE | B40: CONTEO DE ALUMNOS
A41: FEBRERO | B41: 713
A42: MARZO | B42: 1358
A43: ABRIL | B43: 1073
A44: MAYO | B44: 298
A45: JUNIO
...

Sheet 5 – GRAFICOS
B128: Acro Kids | C128: 72
B129: Boxeo | C129: 520 | K129: Agus | L129: 186
B130: Calistenia | C130: 1058 | K130: Edd | L130: 295
B131: Cross Traning | C131: 33 | K131: Lazaro | L131: 150
B132: EFA | C132: 101 | K132: Lean | L132: 15
B133: Funcional | C133: 915 | K133: Marco | L133: 191
B134: JIU JITSU | C134: 24 | K134: Mariano | L134: 313
B135: Karate | C135: 17 | K135: Martin | L135: 332
B136: Lyra | C136: 89 | K136: Paula | L136: 64
B137: MMA | C137: 37 | K137: tito | L137: 207
B138: MMA+BOXEO | C138: 25
B139: Movimiento Consciente | C139: 36
B140: Nutricion
B141: Personalizados | C141: 206
B142: Pole Sport | C142: 216
B143: Taekwondo | C143: 7
B144: Tela | C144: 54
B145: Yoga y Yoga Columpio | C145: 32

Sheet MAPEO
A1: N° | B1: ACTIVIDADES | C1: MAPEO
A2: 1 | B2: Calistenia Edd | C2: Calistenia | D2: Edd
A3: 2 | B3: Calistenia Martin | C3: Calistenia | D3: Martin
A4: 3 | B4: Calistenia Agus | C4: Calistenia | D4: Agus
A5: 4 | B5: Calistenia Lazaro | C5: Calistenia | D5: Lazaro
A6: 5 | B6: Calistenia Paula | C6: Calistenia | D6: Paula
A7: 6 | B7: Boxeo y Kickboxing Mariano | C7: Boxeo | D7: Mariano
A8: 7 | B8: Boxeo tito | C8: Boxeo | D8: tito
A9: 8 | B9: MMA+BOXEO | C9: MMA+BOXEO
A10: 9 | B10: Karate | C10: Karate
A11: 10 | B11: Taekwondo | C11: Taekwondo
A12: 11 | B12: Tela | C12: Tela
A13: 12 | B13: Lyra | C13: Lyra
A14: 13 | B14: Yoga y Yoga Columpio | C14: Yoga y Yoga Columpio
A15: 14 | B15: Pole Sport | C15: Pole Sport
A16: 15 | B16: Acro Kids | C16: Acro Kids
A17: 16 | B17: Calistenia Kids | C17: Calistenia
A18: 17 | B18: Movimiento Consciente | C18: Movimiento Consciente
A19: 18 | B19: Cross Traning | C19: Cross Traning
A20: 19 | B20: Funcional | C20: Funcional
A21: 20 | B21: EFA | C21: EFA
A22: 21 | B22: Personalizados Marco | C22: Personalizados | D22: Marco
A23: 22 | B23: Personalizados Lean | C23: Personalizados | D23: Lean
A24: 23 | B24: MMA | C24: MMA
A25: 24 | B25: JIU JITSU | C25: JIU JITSU
A26: 25 | B26: Nutricion | C26: Nutricion
A27: 26 | B27: Calistenia / CALI KIDS Agus | C27: Calistenia | D27: Agus
